<robot name="onshape">
<link name="body">
<!-- Shapes for prt0006 -->
<!-- Shapes for f3 -->
<collision>
<origin xyz="0.032000000000000007605 0.035350000000000006417 -0.016000000000000000333" rpy="-1.570796326794896558 -0 -1.570796326794896558" />
<geometry>
<box size="0.0043000000000000000028 0.037999999999999999056 0.025000000000000001388" />
</geometry>
</collision>
<!-- Shapes for f3 -->
<collision>
<origin xyz="0.032000000000000007605 -0.039649999999999990807 -0.016000000000000000333" rpy="-1.570796326794896558 -0 -1.570796326794896558" />
<geometry>
<box size="0.0043000000000000000028 0.037999999999999999056 0.025000000000000001388" />
</geometry>
</collision>
<!-- Shapes for f3 -->
<collision>
<origin xyz="0.032000000000000007605 0.039650000000000004685 -0.016000000000000000333" rpy="-1.570796326794896558 -0 1.570796326794896558" />
<geometry>
<box size="0.0043000000000000000028 0.037999999999999999056 0.025000000000000001388" />
</geometry>
</collision>
<!-- Shapes for f3 -->
<collision>
<origin xyz="0.051349999999999999811 0 -0.016000000000000000333" rpy="-1.570796326794896558 -0 3.141592653589793116" />
<geometry>
<box size="0.0043000000000000000028 0.037999999999999999056 0.025000000000000001388" />
</geometry>
</collision>
<!-- Shapes for f3 -->
<collision>
<origin xyz="-0.032000000000000000666 0.035350000000000034173 -0.016000000000000000333" rpy="-1.570796326794896558 -0 -1.570796326794896558" />
<geometry>
<box size="0.0043000000000000000028 0.037999999999999999056 0.025000000000000001388" />
</geometry>
</collision>
<!-- Shapes for prt0006 -->
<!-- Shapes for ax123_adaptor_cm5 -->
<collision>
<origin xyz="0 0 -0.016000000000000000333" rpy="0 -0 3.141592653589793116" />
<geometry>
<box size="0.10100000000000000644 0.069000000000000005773 0.032000000000000000666" />
</geometry>
</collision>
<!-- Shapes for f3 -->
<collision>
<origin xyz="0.032000000000000007605 -0.035349999999999999478 -0.016000000000000000333" rpy="-1.570796326794896558 -0 1.570796326794896558" />
<geometry>
<box size="0.0043000000000000000028 0.037999999999999999056 0.025000000000000001388" />
</geometry>
</collision>
<!-- Shapes for prt0006 -->
<!-- Shapes for f3 -->
<collision>
<origin xyz="0.055649999999999998079 0 -0.016000000000000000333" rpy="-1.570796326794896558 -0 0" />
<geometry>
<box size="0.0043000000000000000028 0.037999999999999999056 0.025000000000000001388" />
</geometry>
</collision>
<!-- Shapes for f3 -->
<collision>
<origin xyz="-0.032000000000000000666 -0.035349999999999992539 -0.016000000000000000333" rpy="-1.570796326794896558 -0 1.570796326794896558" />
<geometry>
<box size="0.0043000000000000000028 0.037999999999999999056 0.025000000000000001388" />
</geometry>
</collision>
<!-- Shapes for prt0001 -->
<collision>
<origin xyz="0.032000000000000007605 -0.065499999999999988787 -0.015800000000000001543" rpy="0 -0 0" />
<geometry>
<box size="0.032000000000000000666 0.050000000000000002776 0.032399999999999998246" />
</geometry>
</collision>
<!-- Shapes for prt0006 -->
<!-- Shapes for prt0006 -->
<!-- Shapes for prt0006 -->
<!-- Shapes for prt0001 -->
<collision>
<origin xyz="0.032000000000000007605 0.065500000000000016542 -0.015800000000000001543" rpy="0 -0 3.141592653589793116" />
<geometry>
<box size="0.032000000000000000666 0.050000000000000002776 0.032399999999999998246" />
</geometry>
</collision>
<!-- Shapes for prt0001 -->
<collision>
<origin xyz="-0.031999999999999993727 0.065500000000000016542 -0.015800000000000001543" rpy="0 -0 3.141592653589793116" />
<geometry>
<box size="0.032000000000000000666 0.050000000000000002776 0.032399999999999998246" />
</geometry>
</collision>
<!-- Shapes for f3 -->
<collision>
<origin xyz="-0.055649999999999998079 0 -0.016000000000000007272" rpy="-1.570796326794896558 1.1102230246251562939e-16 3.141592653589793116" />
<geometry>
<box size="0.0043000000000000000028 0.037999999999999999056 0.025000000000000001388" />
</geometry>
</collision>
<!-- Shapes for f3 -->
<collision>
<origin xyz="-0.032000000000000000666 0.039650000000000004685 -0.016000000000000000333" rpy="-1.570796326794896558 -0 1.570796326794896558" />
<geometry>
<box size="0.0043000000000000000028 0.037999999999999999056 0.025000000000000001388" />
</geometry>
</collision>
<!-- Shapes for f3 -->
<collision>
<origin xyz="-0.051349999999999999811 0 -0.016000000000000000333" rpy="-1.570796326794896558 -0 0" />
<geometry>
<box size="0.0043000000000000000028 0.037999999999999999056 0.025000000000000001388" />
</geometry>
</collision>
<!-- Shapes for f3 -->
<collision>
<origin xyz="-0.032000000000000000666 -0.039649999999999990807 -0.016000000000000000333" rpy="-1.570796326794896558 -0 -1.570796326794896558" />
<geometry>
<box size="0.0043000000000000000028 0.037999999999999999056 0.025000000000000001388" />
</geometry>
</collision>
<!-- Shapes for prt0001 -->
<collision>
<origin xyz="-0.032000000000000000666 -0.065499999999999988787 -0.015800000000000001543" rpy="0 -0 0" />
<geometry>
<box size="0.032000000000000000666 0.050000000000000002776 0.032399999999999998246" />
</geometry>
</collision>
<!-- Shapes for prt0001 -->
<collision>
<origin xyz="0.081500000000000030753 0 -0.015800000000000001543" rpy="0 -0 1.570796326794896558" />
<geometry>
<box size="0.032000000000000000666 0.050000000000000002776 0.032399999999999998246" />
</geometry>
</collision>
<!-- Shapes for prt0001 -->
<collision>
<origin xyz="-0.08149999999999998912 -2.2204460492502996456e-20 -0.015800000000000008482" rpy="1.1102230246251565404e-16 -1.1102230246251560474e-16 -1.570796326794896558" />
<geometry>
<box size="0.032000000000000000666 0.050000000000000002776 0.032399999999999998246" />
</geometry>
</collision>
<visual>
<origin xyz="0 0 0" rpy="0 -0 0" />
<geometry>
<mesh filename="package:///body_visual.stl"/>
</geometry>
<material name="body_material">
<color rgba="0.59265566600678842857 0.58733441893251148169 0.57225755222206031725 1.0"/>
</material>
</visual>
<inertial>
<origin xyz="3.4235565708490930351e-17 -5.3264611426996225528e-17 -0.014591079637799557814" rpy="0 0 0"/>
<mass value="0.34202395142368996472" />
<inertia ixx="0.00090770514054412383513" ixy="1.2368741741144997807e-07"  ixz="-6.3103954570445375261e-20" iyy="0.00094740729227736869382" iyz="8.8721738141212642351e-20" izz="0.001779180310385669421" />
</inertial>
</link>

<link name="segment1">
<!-- Shapes for f2 -->
<collision>
<origin xyz="0 -0.0074999999999999997224 0.043700000000000002731" rpy="-3.141592653589793116 1.570796326794896558 0" />
<geometry>
<box size="0.0033999999999999998106 0.036999999999999998168 0.025000000000000001388" />
</geometry>
</collision>
<collision>
<origin xyz="0 -0.022499999999999999167 0.021000000000000001305" rpy="-3.141592653589793116 1.570796326794896558 0" />
<geometry>
<box size="0.048799999999999996159 0.0070000000000000001457 0.025000000000000001388" />
</geometry>
</collision>
<collision>
<origin xyz="0 -0.0074999999999999997224 -0.0016999999999999966527" rpy="-0 -1.570796326794896558 0" />
<geometry>
<box size="0.0033999999999999998106 0.036999999999999998168 0.025000000000000001388" />
</geometry>
</collision>
<!-- Shapes for f1 -->
<collision>
<origin xyz="0 -0.029000000000000015349 0.020999999999999990896" rpy="3.141592653589793116 -0 0" />
<geometry>
<box size="0.048000000000000000999 0.0060000000000000001249 0.025000000000000001388" />
</geometry>
</collision>
<visual>
<origin xyz="0 0 0" rpy="0 -0 0" />
<geometry>
<mesh filename="package:///segment1_visual.stl"/>
</geometry>
<material name="segment1_material">
<color rgba="0.90196078431372550543 0.87843137254901959565 0.81176470588235294379 1.0"/>
</material>
</visual>
<inertial>
<origin xyz="1.0923468721934355308e-06 -0.026399668925609690723 0.022973185420021052794" rpy="0 0 0"/>
<mass value="0.016044750372786714676" />
<inertia ixx="6.8884928697577646296e-06" ixy="-3.3294419968167234695e-11"  ixz="3.4582901831144849148e-11" iyy="6.8184578480129727398e-06" iyz="6.5121638690356334061e-07" izz="6.8411800542906683518e-06" />
</inertial>
</link>

<link name="segment2">
<!-- Shapes for prt0006 -->
<!-- Shapes for prt0006 -->
<!-- Shapes for prt0001 -->
<collision>
<origin xyz="-0.013500000000000001582 0 -0.019899999999999994083" rpy="0 -0 1.570796326794896558" />
<geometry>
<box size="0.032000000000000000666 0.050000000000000002776 0.032399999999999998246" />
</geometry>
</collision>
<!-- Shapes for f3 -->
<collision>
<origin xyz="-0.03935000000000000997 0 -0.020099999999999992872" rpy="-1.570796326794896558 -0 0" />
<geometry>
<box size="0.0043000000000000000028 0.037999999999999999056 0.025000000000000001388" />
</geometry>
</collision>
<!-- Shapes for f3 -->
<collision>
<origin xyz="-0.043650000000000008238 0 -0.020099999999999992872" rpy="-1.570796326794896558 -0 3.141592653589793116" />
<geometry>
<box size="0.0043000000000000000028 0.037999999999999999056 0.025000000000000001388" />
</geometry>
</collision>
<!-- Shapes for prt0001 -->
<collision>
<origin xyz="-0.060499999999999998224 0.0089999999999999906464 -0.019899999999999994083" rpy="0 -0 3.141592653589793116" />
<geometry>
<box size="0.032000000000000000666 0.050000000000000002776 0.032399999999999998246" />
</geometry>
</collision>
<visual>
<origin xyz="0 0 0" rpy="0 -0 0" />
<geometry>
<mesh filename="package:///segment2_visual.stl"/>
</geometry>
<material name="segment2_material">
<color rgba="0.53065504220586057205 0.52898364604661562982 0.52424802359542155283 1.0"/>
</material>
</visual>
<inertial>
<origin xyz="-0.037016831520621309992 0.0045137137322821983473 -0.019140437647307891045" rpy="0 0 0"/>
<mass value="0.094970933440056581887" />
<inertia ixx="2.3243481497663799818e-05" ixy="1.0010897413922899976e-05"  ixz="-1.1051629383696597312e-07" iyy="7.1068074999376993446e-05" iyz="-1.1236792301126593791e-07" izz="7.4511947663982909269e-05" />
</inertial>
</link>

<link name="segment3">
<!-- Shapes for f4 -->
<collision>
<origin xyz="0 0.04585000000000009901 0.021000000000000004774" rpy="-0 1.570796326794896558 0" />
<geometry>
<box size="0.048000000000000000999 0.015699999999999998679 0.029000000000000001471" />
</geometry>
</collision>
<collision>
<origin xyz="0 0.021350000000000098066 -0.0014999999999999943934" rpy="-3.141592653589793116 -1.570796326794896558 0" />
<geometry>
<box size="0.0030000000000000000625 0.064700000000000007505 0.029000000000000001471" />
</geometry>
</collision>
<collision>
<origin xyz="0 0.021350000000000101535 0.043500000000000003941" rpy="-0 1.570796326794896558 0" />
<geometry>
<box size="0.0030000000000000000625 0.064700000000000007505 0.029000000000000001471" />
</geometry>
</collision>
<!-- Shapes for f6 -->
<collision>
<origin xyz="0.0090000000000000131978 0.072499999999999092948 0.02100000000000003253" rpy="1.570796326794896558 -0 1.570796326794896558" />
<geometry>
<box size="0.041000000000000001721 0.025000000000000001388 0.00899999999999999932" />
</geometry>
</collision>
<visual>
<origin xyz="0 0 0" rpy="0 -0 0" />
<geometry>
<mesh filename="package:///segment3_visual.stl"/>
</geometry>
<material name="segment3_material">
<color rgba="0.90196078431372550543 0.87843137254901970667 0.81176470588235305481 1.0"/>
</material>
</visual>
<inertial>
<origin xyz="0.0025954970530961121375 0.039161593937512180486 0.021000061499635548634" rpy="0 0 0"/>
<mass value="0.01707949220713730204" />
<inertia ixx="1.4424520102109508648e-05" ixy="-1.2065474106601946738e-06"  ixz="-9.1243324066424739086e-13" iyy="6.7952717509329697225e-06" iyz="4.4363323612224916907e-11" izz="1.0361261508764951149e-05" />
</inertial>
</link>

<joint name="leg1_m3" type="revolute">
<origin xyz="-0.060499999999999998224 0.022499999999999978351 0" rpy="3.141592653589793116 -0 3.141592653589793116" />
<parent link="segment2" />
<child link="segment3" />
<axis xyz="0 0 1"/>
<limit effort="1" velocity="20" />
<joint_properties friction="0.0"/>
</joint>

<joint name="leg1_m2" type="revolute">
<origin xyz="0.021000000000000004774 -0.049000000000000015765 0.035499999999999989897" rpy="1.570796326794896558 -0 1.570796326794896558" />
<parent link="segment1" />
<child link="segment2" />
<axis xyz="0 0 1"/>
<limit effort="1" velocity="20" />
<joint_properties friction="0.0"/>
</joint>

<joint name="leg1_m1" type="revolute">
<origin xyz="0.032000000000000000666 0.079000000000000014655 0.0041000000000000029476" rpy="3.141592653589793116 -0 0" />
<parent link="body" />
<child link="segment1" />
<axis xyz="0 0 1"/>
<limit effort="1" velocity="20" />
<joint_properties friction="0.0"/>
</joint>

<link name="segment1_2">
<!-- Shapes for f1 -->
<collision>
<origin xyz="0 -0.029000000000000015349 0.020999999999999990896" rpy="3.141592653589793116 -0 0" />
<geometry>
<box size="0.048000000000000000999 0.0060000000000000001249 0.025000000000000001388" />
</geometry>
</collision>
<!-- Shapes for f2 -->
<collision>
<origin xyz="0 -0.0074999999999999997224 0.043700000000000002731" rpy="-3.141592653589793116 1.570796326794896558 0" />
<geometry>
<box size="0.0033999999999999998106 0.036999999999999998168 0.025000000000000001388" />
</geometry>
</collision>
<collision>
<origin xyz="0 -0.022499999999999999167 0.021000000000000001305" rpy="-3.141592653589793116 1.570796326794896558 0" />
<geometry>
<box size="0.048799999999999996159 0.0070000000000000001457 0.025000000000000001388" />
</geometry>
</collision>
<collision>
<origin xyz="0 -0.0074999999999999997224 -0.0016999999999999966527" rpy="-0 -1.570796326794896558 0" />
<geometry>
<box size="0.0033999999999999998106 0.036999999999999998168 0.025000000000000001388" />
</geometry>
</collision>
<visual>
<origin xyz="0 0 0" rpy="0 -0 0" />
<geometry>
<mesh filename="package:///segment1_2_visual.stl"/>
</geometry>
<material name="segment1_2_material">
<color rgba="0.90196078431372550543 0.87843137254901959565 0.81176470588235294379 1.0"/>
</material>
</visual>
<inertial>
<origin xyz="1.0923468721934355308e-06 -0.026399668925609690723 0.022973185420021052794" rpy="0 0 0"/>
<mass value="0.016044750372786714676" />
<inertia ixx="6.8884928697577646296e-06" ixy="-3.3294419968167234695e-11"  ixz="3.4582901831144849148e-11" iyy="6.8184578480129727398e-06" iyz="6.5121638690356334061e-07" izz="6.8411800542906683518e-06" />
</inertial>
</link>

<link name="segment2_2">
<!-- Shapes for prt0001 -->
<collision>
<origin xyz="-0.060499999999999970468 0.0089999999999999906464 -0.019899999999999994083" rpy="0 -0 3.141592653589793116" />
<geometry>
<box size="0.032000000000000000666 0.050000000000000002776 0.032399999999999998246" />
</geometry>
</collision>
<!-- Shapes for f3 -->
<collision>
<origin xyz="-0.043650000000000008238 0 -0.020099999999999992872" rpy="-1.570796326794896558 -0 3.141592653589793116" />
<geometry>
<box size="0.0043000000000000000028 0.037999999999999999056 0.025000000000000001388" />
</geometry>
</collision>
<!-- Shapes for prt0006 -->
<!-- Shapes for f3 -->
<collision>
<origin xyz="-0.03935000000000000997 0 -0.020099999999999992872" rpy="-1.570796326794896558 -0 0" />
<geometry>
<box size="0.0043000000000000000028 0.037999999999999999056 0.025000000000000001388" />
</geometry>
</collision>
<!-- Shapes for prt0006 -->
<!-- Shapes for prt0001 -->
<collision>
<origin xyz="-0.013500000000000001582 0 -0.019899999999999994083" rpy="0 -0 1.570796326794896558" />
<geometry>
<box size="0.032000000000000000666 0.050000000000000002776 0.032399999999999998246" />
</geometry>
</collision>
<visual>
<origin xyz="0 0 0" rpy="0 -0 0" />
<geometry>
<mesh filename="package:///segment2_2_visual.stl"/>
</geometry>
<material name="segment2_2_material">
<color rgba="0.53065504220586057205 0.52898364604661562982 0.52424802359542155283 1.0"/>
</material>
</visual>
<inertial>
<origin xyz="-0.037016831520621296114 0.0045137137322821983473 -0.019140437647307887575" rpy="0 0 0"/>
<mass value="0.094970933440056581887" />
<inertia ixx="2.3243481497663799818e-05" ixy="1.0010897413922894894e-05"  ixz="-1.1051629383696613194e-07" iyy="7.1068074999376925683e-05" iyz="-1.1236792301126600409e-07" izz="7.4511947663982855058e-05" />
</inertial>
</link>

<link name="segment3_2">
<!-- Shapes for f6 -->
<collision>
<origin xyz="0.0090000000000000131978 0.072499999999999092948 0.021000000000000001305" rpy="1.570796326794896558 -0 1.570796326794896558" />
<geometry>
<box size="0.041000000000000001721 0.025000000000000001388 0.00899999999999999932" />
</geometry>
</collision>
<!-- Shapes for f4 -->
<collision>
<origin xyz="0 0.04585000000000009901 0.021000000000000001305" rpy="-0 1.570796326794896558 0" />
<geometry>
<box size="0.048000000000000000999 0.015699999999999998679 0.029000000000000001471" />
</geometry>
</collision>
<collision>
<origin xyz="0 0.021350000000000098066 -0.0014999999999999978628" rpy="-3.141592653589793116 -1.570796326794896558 0" />
<geometry>
<box size="0.0030000000000000000625 0.064700000000000007505 0.029000000000000001471" />
</geometry>
</collision>
<collision>
<origin xyz="0 0.021350000000000101535 0.043499999999999997002" rpy="-0 1.570796326794896558 0" />
<geometry>
<box size="0.0030000000000000000625 0.064700000000000007505 0.029000000000000001471" />
</geometry>
</collision>
<visual>
<origin xyz="0 0 0" rpy="0 -0 0" />
<geometry>
<mesh filename="package:///segment3_2_visual.stl"/>
</geometry>
<material name="segment3_2_material">
<color rgba="0.90196078431372550543 0.87843137254901970667 0.81176470588235305481 1.0"/>
</material>
</visual>
<inertial>
<origin xyz="0.0025954970530961121375 0.039161593937512180486 0.021000061499635541695" rpy="0 0 0"/>
<mass value="0.01707949220713730204" />
<inertia ixx="1.4424520102109512036e-05" ixy="-1.2065474106601948856e-06"  ixz="-9.1243323989383649071e-13" iyy="6.7952717509329697225e-06" iyz="4.4363323615090974944e-11" izz="1.0361261508764954537e-05" />
</inertial>
</link>

<joint name="leg2_m3" type="revolute">
<origin xyz="-0.060499999999999970468 0.022499999999999992228 -1.7347234759768070944e-18" rpy="3.141592653589793116 -0 3.141592653589793116" />
<parent link="segment2_2" />
<child link="segment3_2" />
<axis xyz="0 0 1"/>
<limit effort="1" velocity="20" />
<joint_properties friction="0.0"/>
</joint>

<joint name="leg2_m2" type="revolute">
<origin xyz="0.021000000000000004774 -0.049000000000000015765 0.035499999999999989897" rpy="1.570796326794896558 -0 1.570796326794896558" />
<parent link="segment1_2" />
<child link="segment2_2" />
<axis xyz="0 0 1"/>
<limit effort="1" velocity="20" />
<joint_properties friction="0.0"/>
</joint>

<joint name="leg2_m1" type="revolute">
<origin xyz="-0.032000000000000000666 0.079000000000000014655 0.0040999999999999960087" rpy="3.141592653589793116 -0 0" />
<parent link="body" />
<child link="segment1_2" />
<axis xyz="0 0 1"/>
<limit effort="1" velocity="20" />
<joint_properties friction="0.0"/>
</joint>

<link name="segment1_3">
<!-- Shapes for f1 -->
<collision>
<origin xyz="1.2267964422107981423e-17 -0.029000000000000015349 0.020999999999999990896" rpy="3.141592653589793116 -0 0" />
<geometry>
<box size="0.048000000000000000999 0.0060000000000000001249 0.025000000000000001388" />
</geometry>
</collision>
<!-- Shapes for f2 -->
<collision>
<origin xyz="0 -0.0074999999999999997224 0.043700000000000002731" rpy="-3.141592653589793116 1.570796326794896558 0" />
<geometry>
<box size="0.0033999999999999998106 0.036999999999999998168 0.025000000000000001388" />
</geometry>
</collision>
<collision>
<origin xyz="0 -0.022499999999999999167 0.021000000000000001305" rpy="-3.141592653589793116 1.570796326794896558 0" />
<geometry>
<box size="0.048799999999999996159 0.0070000000000000001457 0.025000000000000001388" />
</geometry>
</collision>
<collision>
<origin xyz="0 -0.0074999999999999997224 -0.0016999999999999966527" rpy="-0 -1.570796326794896558 0" />
<geometry>
<box size="0.0033999999999999998106 0.036999999999999998168 0.025000000000000001388" />
</geometry>
</collision>
<visual>
<origin xyz="0 0 0" rpy="0 -0 0" />
<geometry>
<mesh filename="package:///segment1_3_visual.stl"/>
</geometry>
<material name="segment1_3_material">
<color rgba="0.90196078431372550543 0.87843137254901959565 0.81176470588235294379 1.0"/>
</material>
</visual>
<inertial>
<origin xyz="1.0923468721998384646e-06 -0.026399668925609690723 0.022973185420021052794" rpy="0 0 0"/>
<mass value="0.016044750372786714676" />
<inertia ixx="6.8884928697577646296e-06" ixy="-3.3294419967102032861e-11"  ixz="3.4582901830959166487e-11" iyy="6.8184578480129727398e-06" iyz="6.5121638690356334061e-07" izz="6.8411800542906683518e-06" />
</inertial>
</link>

<link name="segment2_3">
<!-- Shapes for prt0006 -->
<!-- Shapes for prt0006 -->
<!-- Shapes for prt0001 -->
<collision>
<origin xyz="-0.060499999999999998224 0.0089999999999999837075 -0.019900000000000004491" rpy="0 -0 3.141592653589793116" />
<geometry>
<box size="0.032000000000000000666 0.050000000000000002776 0.032399999999999998246" />
</geometry>
</collision>
<!-- Shapes for f3 -->
<collision>
<origin xyz="-0.039350000000000037725 -6.9388939039072283776e-18 -0.020099999999999999811" rpy="-1.570796326794896558 -0 0" />
<geometry>
<box size="0.0043000000000000000028 0.037999999999999999056 0.025000000000000001388" />
</geometry>
</collision>
<!-- Shapes for f3 -->
<collision>
<origin xyz="-0.043650000000000035993 -6.9388939039072283776e-18 -0.020099999999999999811" rpy="-1.570796326794896558 -0 3.141592653589793116" />
<geometry>
<box size="0.0043000000000000000028 0.037999999999999999056 0.025000000000000001388" />
</geometry>
</collision>
<!-- Shapes for prt0001 -->
<collision>
<origin xyz="-0.013500000000000001582 0 -0.019900000000000001021" rpy="0 -0 1.570796326794896558" />
<geometry>
<box size="0.032000000000000000666 0.050000000000000002776 0.032399999999999998246" />
</geometry>
</collision>
<visual>
<origin xyz="0 0 0" rpy="0 -0 0" />
<geometry>
<mesh filename="package:///segment2_3_visual.stl"/>
</geometry>
<material name="segment2_3_material">
<color rgba="0.53065504220586057205 0.52898364604661562982 0.52424802359542155283 1.0"/>
</material>
</visual>
<inertial>
<origin xyz="-0.037016831520621303053 0.0045137137322821948779 -0.019140437647307901453" rpy="0 0 0"/>
<mass value="0.094970933440056581887" />
<inertia ixx="2.3243481497663793042e-05" ixy="1.0010897413922891506e-05"  ixz="-1.1051629383696983771e-07" iyy="7.1068074999376993446e-05" iyz="-1.1236792301126527617e-07" izz="7.4511947663982882164e-05" />
</inertial>
</link>

<link name="segment3_3">
<!-- Shapes for f4 -->
<collision>
<origin xyz="0 0.04585000000000009901 0.021000000000000001305" rpy="-0 1.570796326794896558 0" />
<geometry>
<box size="0.048000000000000000999 0.015699999999999998679 0.029000000000000001471" />
</geometry>
</collision>
<collision>
<origin xyz="0 0.021350000000000098066 -0.0014999999999999978628" rpy="-3.141592653589793116 -1.570796326794896558 0" />
<geometry>
<box size="0.0030000000000000000625 0.064700000000000007505 0.029000000000000001471" />
</geometry>
</collision>
<collision>
<origin xyz="0 0.021350000000000101535 0.043499999999999997002" rpy="-0 1.570796326794896558 0" />
<geometry>
<box size="0.0030000000000000000625 0.064700000000000007505 0.029000000000000001471" />
</geometry>
</collision>
<!-- Shapes for f6 -->
<collision>
<origin xyz="0.0090000000000000131978 0.072499999999999092948 0.021000000000000004774" rpy="1.570796326794896558 -0 1.570796326794896558" />
<geometry>
<box size="0.041000000000000001721 0.025000000000000001388 0.00899999999999999932" />
</geometry>
</collision>
<visual>
<origin xyz="0 0 0" rpy="0 -0 0" />
<geometry>
<mesh filename="package:///segment3_3_visual.stl"/>
</geometry>
<material name="segment3_3_material">
<color rgba="0.90196078431372550543 0.87843137254901970667 0.81176470588235305481 1.0"/>
</material>
</visual>
<inertial>
<origin xyz="0.0025954970530961121375 0.039161593937512180486 0.021000061499635541695" rpy="0 0 0"/>
<mass value="0.01707949220713730204" />
<inertia ixx="1.4424520102109512036e-05" ixy="-1.2065474106601948856e-06"  ixz="-9.1243323999013800469e-13" iyy="6.7952717509329697225e-06" iyz="4.4363323614732715266e-11" izz="1.0361261508764954537e-05" />
</inertial>
</link>

<joint name="leg3_m3" type="revolute">
<origin xyz="-0.060499999999999998224 0.02249999999999998529 -1.3877787807814456755e-17" rpy="3.141592653589793116 -0 3.141592653589793116" />
<parent link="segment2_3" />
<child link="segment3_3" />
<axis xyz="0 0 1"/>
<limit effort="1" velocity="20" />
<joint_properties friction="0.0"/>
</joint>

<joint name="leg3_m2" type="revolute">
<origin xyz="0.021000000000000011713 -0.049000000000000015765 0.035499999999999996836" rpy="1.570796326794896558 2.2204460492503130808e-16 1.570796326794896558" />
<parent link="segment1_3" />
<child link="segment2_3" />
<axis xyz="0 0 1"/>
<limit effort="1" velocity="20" />
<joint_properties friction="0.0"/>
</joint>

<joint name="leg3_m1" type="revolute">
<origin xyz="-0.09500000000000000111 -2.3314683517128288797e-18 0.0040999999999999890699" rpy="-3.141592653589793116 -1.1102230246251565404e-16 1.570796326794896558" />
<parent link="body" />
<child link="segment1_3" />
<axis xyz="0 0 1"/>
<limit effort="1" velocity="20" />
<joint_properties friction="0.0"/>
</joint>

<link name="segment1_4">
<!-- Shapes for f2 -->
<collision>
<origin xyz="0 -0.0074999999999999997224 0.043700000000000002731" rpy="-3.141592653589793116 1.570796326794896558 0" />
<geometry>
<box size="0.0033999999999999998106 0.036999999999999998168 0.025000000000000001388" />
</geometry>
</collision>
<collision>
<origin xyz="0 -0.022499999999999999167 0.021000000000000001305" rpy="-3.141592653589793116 1.570796326794896558 0" />
<geometry>
<box size="0.048799999999999996159 0.0070000000000000001457 0.025000000000000001388" />
</geometry>
</collision>
<collision>
<origin xyz="0 -0.0074999999999999997224 -0.0016999999999999966527" rpy="-0 -1.570796326794896558 0" />
<geometry>
<box size="0.0033999999999999998106 0.036999999999999998168 0.025000000000000001388" />
</geometry>
</collision>
<!-- Shapes for f1 -->
<collision>
<origin xyz="0 -0.029000000000000015349 0.020999999999999990896" rpy="3.141592653589793116 -0 0" />
<geometry>
<box size="0.048000000000000000999 0.0060000000000000001249 0.025000000000000001388" />
</geometry>
</collision>
<visual>
<origin xyz="0 0 0" rpy="0 -0 0" />
<geometry>
<mesh filename="package:///segment1_4_visual.stl"/>
</geometry>
<material name="segment1_4_material">
<color rgba="0.90196078431372550543 0.87843137254901959565 0.81176470588235294379 1.0"/>
</material>
</visual>
<inertial>
<origin xyz="1.0923468721934355308e-06 -0.026399668925609690723 0.022973185420021052794" rpy="0 0 0"/>
<mass value="0.016044750372786714676" />
<inertia ixx="6.8884928697577646296e-06" ixy="-3.3294419968167234695e-11"  ixz="3.4582901831144849148e-11" iyy="6.8184578480129727398e-06" iyz="6.5121638690356334061e-07" izz="6.8411800542906683518e-06" />
</inertial>
</link>

<link name="segment2_4">
<!-- Shapes for f3 -->
<collision>
<origin xyz="-0.043649999999999980482 0 -0.020099999999999985933" rpy="-1.570796326794896558 -0 3.141592653589793116" />
<geometry>
<box size="0.0043000000000000000028 0.037999999999999999056 0.025000000000000001388" />
</geometry>
</collision>
<!-- Shapes for prt0001 -->
<collision>
<origin xyz="-0.013500000000000001582 0 -0.019899999999999987144" rpy="0 -0 1.570796326794896558" />
<geometry>
<box size="0.032000000000000000666 0.050000000000000002776 0.032399999999999998246" />
</geometry>
</collision>
<!-- Shapes for prt0006 -->
<!-- Shapes for prt0006 -->
<!-- Shapes for f3 -->
<collision>
<origin xyz="-0.039349999999999982214 0 -0.020099999999999985933" rpy="-1.570796326794896558 -0 0" />
<geometry>
<box size="0.0043000000000000000028 0.037999999999999999056 0.025000000000000001388" />
</geometry>
</collision>
<!-- Shapes for prt0001 -->
<collision>
<origin xyz="-0.060499999999999998224 0.0089999999999999906464 -0.019899999999999987144" rpy="0 -0 3.141592653589793116" />
<geometry>
<box size="0.032000000000000000666 0.050000000000000002776 0.032399999999999998246" />
</geometry>
</collision>
<visual>
<origin xyz="0 0 0" rpy="0 -0 0" />
<geometry>
<mesh filename="package:///segment2_4_visual.stl"/>
</geometry>
<material name="segment2_4_material">
<color rgba="0.53065504220586057205 0.52898364604661562982 0.52424802359542155283 1.0"/>
</material>
</visual>
<inertial>
<origin xyz="-0.037016831520621303053 0.0045137137322821983473 -0.019140437647307880636" rpy="0 0 0"/>
<mass value="0.094970933440056581887" />
<inertia ixx="2.3243481497663799818e-05" ixy="1.001089741392290167e-05"  ixz="-1.1051629383696576136e-07" iyy="7.1068074999376979893e-05" iyz="-1.1236792301126577909e-07" izz="7.4511947663982909269e-05" />
</inertial>
</link>

<link name="segment3_4">
<!-- Shapes for f6 -->
<collision>
<origin xyz="0.0090000000000000131978 0.072499999999999092948 0.021000000000000018652" rpy="1.570796326794896558 -0 1.570796326794896558" />
<geometry>
<box size="0.041000000000000001721 0.025000000000000001388 0.00899999999999999932" />
</geometry>
</collision>
<!-- Shapes for f4 -->
<collision>
<origin xyz="1.4128622072024757661e-33 0.04585000000000009901 0.021000000000000004774" rpy="-0 1.570796326794896558 0" />
<geometry>
<box size="0.048000000000000000999 0.015699999999999998679 0.029000000000000001471" />
</geometry>
</collision>
<collision>
<origin xyz="6.5789766900267958198e-34 0.021350000000000098066 -0.0014999999999999943934" rpy="-3.141592653589793116 -1.570796326794896558 0" />
<geometry>
<box size="0.0030000000000000000625 0.064700000000000007505 0.029000000000000001471" />
</geometry>
</collision>
<collision>
<origin xyz="6.5789766900267966751e-34 0.021350000000000101535 0.043500000000000003941" rpy="-0 1.570796326794896558 0" />
<geometry>
<box size="0.0030000000000000000625 0.064700000000000007505 0.029000000000000001471" />
</geometry>
</collision>
<visual>
<origin xyz="0 0 0" rpy="0 -0 0" />
<geometry>
<mesh filename="package:///segment3_4_visual.stl"/>
</geometry>
<material name="segment3_4_material">
<color rgba="0.90196078431372550543 0.87843137254901970667 0.81176470588235305481 1.0"/>
</material>
</visual>
<inertial>
<origin xyz="0.0025954970530961121375 0.039161593937512180486 0.021000061499635545165" rpy="0 0 0"/>
<mass value="0.01707949220713730204" />
<inertia ixx="1.4424520102109512036e-05" ixy="-1.2065474106601948856e-06"  ixz="-9.1243324027904194079e-13" iyy="6.7952717509329697225e-06" iyz="4.4363323613657942694e-11" izz="1.0361261508764954537e-05" />
</inertial>
</link>

<joint name="leg4_m3" type="revolute">
<origin xyz="-0.060499999999999998224 0.022500000000000006106 -6.9388939039072283776e-18" rpy="3.141592653589793116 -0 3.141592653589793116" />
<parent link="segment2_4" />
<child link="segment3_4" />
<axis xyz="0 0 1"/>
<limit effort="1" velocity="20" />
<joint_properties friction="0.0"/>
</joint>

<joint name="leg4_m2" type="revolute">
<origin xyz="0.021000000000000011713 -0.049000000000000015765 0.035499999999999989897" rpy="1.570796326794896558 -0 1.570796326794896558" />
<parent link="segment1_4" />
<child link="segment2_4" />
<axis xyz="0 0 1"/>
<limit effort="1" velocity="20" />
<joint_properties friction="0.0"/>
</joint>

<joint name="leg4_m1" type="revolute">
<origin xyz="-0.032000000000000000666 -0.078999999999999986899 0.0040999999999999960087" rpy="3.141592653589793116 -0 3.141592653589793116" />
<parent link="body" />
<child link="segment1_4" />
<axis xyz="0 0 1"/>
<limit effort="1" velocity="20" />
<joint_properties friction="0.0"/>
</joint>

<link name="segment1_5">
<!-- Shapes for f1 -->
<collision>
<origin xyz="0 -0.029000000000000015349 0.020999999999999990896" rpy="3.141592653589793116 -0 0" />
<geometry>
<box size="0.048000000000000000999 0.0060000000000000001249 0.025000000000000001388" />
</geometry>
</collision>
<!-- Shapes for f2 -->
<collision>
<origin xyz="0 -0.0074999999999999997224 0.043700000000000002731" rpy="-3.141592653589793116 1.570796326794896558 0" />
<geometry>
<box size="0.0033999999999999998106 0.036999999999999998168 0.025000000000000001388" />
</geometry>
</collision>
<collision>
<origin xyz="0 -0.022499999999999999167 0.021000000000000001305" rpy="-3.141592653589793116 1.570796326794896558 0" />
<geometry>
<box size="0.048799999999999996159 0.0070000000000000001457 0.025000000000000001388" />
</geometry>
</collision>
<collision>
<origin xyz="0 -0.0074999999999999997224 -0.0016999999999999966527" rpy="-0 -1.570796326794896558 0" />
<geometry>
<box size="0.0033999999999999998106 0.036999999999999998168 0.025000000000000001388" />
</geometry>
</collision>
<visual>
<origin xyz="0 0 0" rpy="0 -0 0" />
<geometry>
<mesh filename="package:///segment1_5_visual.stl"/>
</geometry>
<material name="segment1_5_material">
<color rgba="0.90196078431372550543 0.87843137254901959565 0.81176470588235294379 1.0"/>
</material>
</visual>
<inertial>
<origin xyz="1.0923468721934355308e-06 -0.026399668925609690723 0.022973185420021052794" rpy="0 0 0"/>
<mass value="0.016044750372786714676" />
<inertia ixx="6.8884928697577646296e-06" ixy="-3.3294419968167234695e-11"  ixz="3.4582901831144849148e-11" iyy="6.8184578480129727398e-06" iyz="6.5121638690356334061e-07" izz="6.8411800542906683518e-06" />
</inertial>
</link>

<link name="segment2_5">
<!-- Shapes for prt0001 -->
<collision>
<origin xyz="-0.013500000000000001582 0 -0.019899999999999994083" rpy="0 -0 1.570796326794896558" />
<geometry>
<box size="0.032000000000000000666 0.050000000000000002776 0.032399999999999998246" />
</geometry>
</collision>
<!-- Shapes for f3 -->
<collision>
<origin xyz="-0.03935000000000000997 0 -0.020099999999999992872" rpy="-1.570796326794896558 -0 0" />
<geometry>
<box size="0.0043000000000000000028 0.037999999999999999056 0.025000000000000001388" />
</geometry>
</collision>
<!-- Shapes for prt0006 -->
<!-- Shapes for prt0001 -->
<collision>
<origin xyz="-0.060500000000000025979 0.0089999999999999975853 -0.019899999999999994083" rpy="0 -0 3.141592653589793116" />
<geometry>
<box size="0.032000000000000000666 0.050000000000000002776 0.032399999999999998246" />
</geometry>
</collision>
<!-- Shapes for f3 -->
<collision>
<origin xyz="-0.043650000000000008238 0 -0.020099999999999992872" rpy="-1.570796326794896558 -0 3.141592653589793116" />
<geometry>
<box size="0.0043000000000000000028 0.037999999999999999056 0.025000000000000001388" />
</geometry>
</collision>
<!-- Shapes for prt0006 -->
<visual>
<origin xyz="0 0 0" rpy="0 -0 0" />
<geometry>
<mesh filename="package:///segment2_5_visual.stl"/>
</geometry>
<material name="segment2_5_material">
<color rgba="0.53065504220586068307 0.52898364604661574084 0.52424802359542166386 1.0"/>
</material>
</visual>
<inertial>
<origin xyz="-0.03701683152062132387 0.0045137137322822018168 -0.019140437647307891045" rpy="0 0 0"/>
<mass value="0.094970933440056568009" />
<inertia ixx="2.3243481497663799818e-05" ixy="1.0010897413922913529e-05"  ixz="-1.1051629383696592018e-07" iyy="7.1068074999377034103e-05" iyz="-1.1236792301126599085e-07" izz="7.4511947663982977031e-05" />
</inertial>
</link>

<link name="segment3_5">
<!-- Shapes for f6 -->
<collision>
<origin xyz="0.0090000000000000131978 0.072499999999999092948 0.021000000000000001305" rpy="1.570796326794896558 -0 1.570796326794896558" />
<geometry>
<box size="0.041000000000000001721 0.025000000000000001388 0.00899999999999999932" />
</geometry>
</collision>
<!-- Shapes for f4 -->
<collision>
<origin xyz="1.4128622072024757661e-33 0.04585000000000009901 0.021000000000000001305" rpy="-0 1.570796326794896558 0" />
<geometry>
<box size="0.048000000000000000999 0.015699999999999998679 0.029000000000000001471" />
</geometry>
</collision>
<collision>
<origin xyz="6.5789766900267958198e-34 0.021350000000000098066 -0.0014999999999999978628" rpy="-3.141592653589793116 -1.570796326794896558 0" />
<geometry>
<box size="0.0030000000000000000625 0.064700000000000007505 0.029000000000000001471" />
</geometry>
</collision>
<collision>
<origin xyz="6.5789766900267966751e-34 0.021350000000000101535 0.043499999999999997002" rpy="-0 1.570796326794896558 0" />
<geometry>
<box size="0.0030000000000000000625 0.064700000000000007505 0.029000000000000001471" />
</geometry>
</collision>
<visual>
<origin xyz="0 0 0" rpy="0 -0 0" />
<geometry>
<mesh filename="package:///segment3_5_visual.stl"/>
</geometry>
<material name="segment3_5_material">
<color rgba="0.90196078431372550543 0.87843137254901970667 0.81176470588235305481 1.0"/>
</material>
</visual>
<inertial>
<origin xyz="0.0025954970530961121375 0.039161593937512180486 0.021000061499635541695" rpy="0 0 0"/>
<mass value="0.01707949220713730204" />
<inertia ixx="1.4424520102109508648e-05" ixy="-1.2065474106601946738e-06"  ixz="-9.1243323989383649071e-13" iyy="6.7952717509329697225e-06" iyz="4.4363323615090968482e-11" izz="1.0361261508764951149e-05" />
</inertial>
</link>

<joint name="leg5_m3" type="revolute">
<origin xyz="-0.060500000000000053735 0.02249999999999998529 -1.7347234759768070944e-18" rpy="3.141592653589793116 -0 3.141592653589793116" />
<parent link="segment2_5" />
<child link="segment3_5" />
<axis xyz="0 0 1"/>
<limit effort="1" velocity="20" />
<joint_properties friction="0.0"/>
</joint>

<joint name="leg5_m2" type="revolute">
<origin xyz="0.020999999999999997835 -0.049000000000000015765 0.035499999999999962141" rpy="1.570796326794896558 -0 1.570796326794896558" />
<parent link="segment1_5" />
<child link="segment2_5" />
<axis xyz="0 0 1"/>
<limit effort="1" velocity="20" />
<joint_properties friction="0.0"/>
</joint>

<joint name="leg5_m1" type="revolute">
<origin xyz="0.032000000000000007605 -0.078999999999999986899 0.0040999999999999960087" rpy="3.141592653589793116 -0 3.141592653589793116" />
<parent link="body" />
<child link="segment1_5" />
<axis xyz="0 0 1"/>
<limit effort="1" velocity="20" />
<joint_properties friction="0.0"/>
</joint>

<link name="segment1_6">
<!-- Shapes for f2 -->
<collision>
<origin xyz="0 -0.0074999999999999997224 0.043700000000000002731" rpy="-3.141592653589793116 1.570796326794896558 0" />
<geometry>
<box size="0.0033999999999999998106 0.036999999999999998168 0.025000000000000001388" />
</geometry>
</collision>
<collision>
<origin xyz="0 -0.022499999999999999167 0.021000000000000001305" rpy="-3.141592653589793116 1.570796326794896558 0" />
<geometry>
<box size="0.048799999999999996159 0.0070000000000000001457 0.025000000000000001388" />
</geometry>
</collision>
<collision>
<origin xyz="0 -0.0074999999999999997224 -0.0016999999999999966527" rpy="-0 -1.570796326794896558 0" />
<geometry>
<box size="0.0033999999999999998106 0.036999999999999998168 0.025000000000000001388" />
</geometry>
</collision>
<!-- Shapes for f1 -->
<collision>
<origin xyz="0 -0.029000000000000015349 0.020999999999999990896" rpy="3.141592653589793116 -0 0" />
<geometry>
<box size="0.048000000000000000999 0.0060000000000000001249 0.025000000000000001388" />
</geometry>
</collision>
<visual>
<origin xyz="0 0 0" rpy="0 -0 0" />
<geometry>
<mesh filename="package:///segment1_6_visual.stl"/>
</geometry>
<material name="segment1_6_material">
<color rgba="0.90196078431372550543 0.87843137254901959565 0.81176470588235294379 1.0"/>
</material>
</visual>
<inertial>
<origin xyz="1.0923468721934355308e-06 -0.026399668925609690723 0.022973185420021052794" rpy="0 0 0"/>
<mass value="0.016044750372786714676" />
<inertia ixx="6.8884928697577646296e-06" ixy="-3.3294419968167234695e-11"  ixz="3.4582901831144849148e-11" iyy="6.8184578480129727398e-06" iyz="6.5121638690356334061e-07" izz="6.8411800542906683518e-06" />
</inertial>
</link>

<link name="segment2_6">
<!-- Shapes for prt0001 -->
<collision>
<origin xyz="-0.013500000000000001582 0 -0.019899999999999973266" rpy="0 -0 1.570796326794896558" />
<geometry>
<box size="0.032000000000000000666 0.050000000000000002776 0.032399999999999998246" />
</geometry>
</collision>
<!-- Shapes for prt0001 -->
<collision>
<origin xyz="-0.060499999999999998224 0.0089999999999999906464 -0.019899999999999973266" rpy="0 -0 3.141592653589793116" />
<geometry>
<box size="0.032000000000000000666 0.050000000000000002776 0.032399999999999998246" />
</geometry>
</collision>
<!-- Shapes for f3 -->
<collision>
<origin xyz="-0.03935000000000000997 0 -0.020099999999999972056" rpy="-1.570796326794896558 -0 0" />
<geometry>
<box size="0.0043000000000000000028 0.037999999999999999056 0.025000000000000001388" />
</geometry>
</collision>
<!-- Shapes for prt0006 -->
<!-- Shapes for prt0006 -->
<!-- Shapes for f3 -->
<collision>
<origin xyz="-0.043650000000000008238 0 -0.020099999999999972056" rpy="-1.570796326794896558 -0 3.141592653589793116" />
<geometry>
<box size="0.0043000000000000000028 0.037999999999999999056 0.025000000000000001388" />
</geometry>
</collision>
<visual>
<origin xyz="0 0 0" rpy="0 -0 0" />
<geometry>
<mesh filename="package:///segment2_6_visual.stl"/>
</geometry>
<material name="segment2_6_material">
<color rgba="0.53065504220586079409 0.52898364604661585187 0.52424802359542166386 1.0"/>
</material>
</visual>
<inertial>
<origin xyz="-0.037016831520621316931 0.0045137137322821992147 -0.019140437647307873698" rpy="0 0 0"/>
<mass value="0.094970933440056554131" />
<inertia ixx="2.3243481497663799818e-05" ixy="1.0010897413922899976e-05"  ixz="-1.1051629383696568195e-07" iyy="7.1068074999376979893e-05" iyz="-1.1236792301126556733e-07" izz="7.4511947663982895716e-05" />
</inertial>
</link>

<link name="segment3_6">
<!-- Shapes for f6 -->
<collision>
<origin xyz="0.0090000000000000131978 0.072499999999999106826 0.021000000000000001305" rpy="1.570796326794896558 -0 1.570796326794896558" />
<geometry>
<box size="0.041000000000000001721 0.025000000000000001388 0.00899999999999999932" />
</geometry>
</collision>
<!-- Shapes for f4 -->
<collision>
<origin xyz="0 0.04585000000000009901 0.021000000000000001305" rpy="-0 1.570796326794896558 0" />
<geometry>
<box size="0.048000000000000000999 0.015699999999999998679 0.029000000000000001471" />
</geometry>
</collision>
<collision>
<origin xyz="0 0.021350000000000098066 -0.0014999999999999978628" rpy="-3.141592653589793116 -1.570796326794896558 0" />
<geometry>
<box size="0.0030000000000000000625 0.064700000000000007505 0.029000000000000001471" />
</geometry>
</collision>
<collision>
<origin xyz="0 0.021350000000000101535 0.043499999999999997002" rpy="-0 1.570796326794896558 0" />
<geometry>
<box size="0.0030000000000000000625 0.064700000000000007505 0.029000000000000001471" />
</geometry>
</collision>
<visual>
<origin xyz="0 0 0" rpy="0 -0 0" />
<geometry>
<mesh filename="package:///segment3_6_visual.stl"/>
</geometry>
<material name="segment3_6_material">
<color rgba="0.90196078431372550543 0.87843137254901970667 0.81176470588235305481 1.0"/>
</material>
</visual>
<inertial>
<origin xyz="0.0025954970530961121375 0.039161593937512180486 0.021000061499635541695" rpy="0 0 0"/>
<mass value="0.01707949220713730204" />
<inertia ixx="1.4424520102109512036e-05" ixy="-1.2065474106601948856e-06"  ixz="-9.1243323989383649071e-13" iyy="6.7952717509329697225e-06" iyz="4.4363323615090974944e-11" izz="1.0361261508764954537e-05" />
</inertial>
</link>

<joint name="leg6_m3" type="revolute">
<origin xyz="-0.060499999999999998224 0.022499999999999992228 1.7347234759768070944e-17" rpy="3.141592653589793116 -0 3.141592653589793116" />
<parent link="segment2_6" />
<child link="segment3_6" />
<axis xyz="0 0 1"/>
<limit effort="1" velocity="20" />
<joint_properties friction="0.0"/>
</joint>

<joint name="leg6_m2" type="revolute">
<origin xyz="0.020999999999999997835 -0.049000000000000015765 0.035499999999999989897" rpy="1.570796326794896558 -0 1.570796326794896558" />
<parent link="segment1_6" />
<child link="segment2_6" />
<axis xyz="0 0 1"/>
<limit effort="1" velocity="20" />
<joint_properties friction="0.0"/>
</joint>

<joint name="leg6_m1" type="revolute">
<origin xyz="0.095000000000000028866 1.3877787807814456755e-17 0.0041000000000000029476" rpy="3.141592653589793116 -0 -1.570796326794896558" />
<parent link="body" />
<child link="segment1_6" />
<axis xyz="0 0 1"/>
<limit effort="1" velocity="20" />
<joint_properties friction="0.0"/>
</joint>


</robot>
